<!DOCTYPE html>
<html lang="en">

<head>
    <meta charset="UTF-8">
    <meta http-equiv="X-UA-Compatible" content="IE=edge">
    <meta name="viewport" content="width=device-width, initial-scale=1.0">
    <title>Document</title>
</head>

<body>

</body>
<script>
    function* testGen() {
        try {
            yield; // 相当于在此处抛出异常，被捕获直接进入catch, catch执行完后继续执行
            console.log('yield after'); // 不执行
        } catch (error) {
            console.log('inner-->', error); //catch方法会自动触发一次next方法
        }
        console.log('inner catch after');
    }
    const gen = testGen();
    gen.next();
    try {
        gen.throw(new Error("gen.throw")); // 被内部捕获
        gen.throw(new Error("gen.throw1")); // 被外部捕获，直接进入catch
        gen.throw(new Error("gen.throw2")); // 不执行
        console.log('gen.throw after'); // 不执行
    } catch (error) {
        console.log('outer-->', error);
    }
    console.log('after');
    // 运行结果
    // inner-- > Error: gen.throw
    // inner  catch after
    //  outer-- > Error: gen.throw1
    //  after
</script>

</html>